<?xml version="1.0" ?>
<!-- Generated using onshape-to-robot (Modified: Fastened links separated - WORKING VERSION) -->
<robot name="KUKA_LBR_iiwa">
  
  <!-- ==================== LINK: base ==================== -->
  <link name="base">
    <inertial>
      <mass value="0.0"/>
      <inertia ixx="0" ixy="0" ixz="0" iyy="0" iyz="0" izz="0"/>
    </inertial>
    <visual>
      <origin xyz="0 0 0.618" rpy="0 0 0"/>
      <geometry>
        <mesh filename="package://assets/base.stl"/>
      </geometry>
      <material name="base_material">
        <color rgba="0.75 0.75 0.75 1"/>
      </material>
    </visual>
    <collision>
      <origin xyz="0 0 0.618" rpy="0 0 0"/>
      <geometry>
        <mesh filename="package://assets/base.stl"/>
      </geometry>
    </collision>
  </link>

  <!-- ==================== LINK: pedestal ==================== -->
  <link name="pedestal">
    <inertial>
      <origin xyz="-1.282e-09 -5.24262e-05 0.308242" rpy="0 0 0"/>
      <mass value="85.5892"/>
      <inertia ixx="4.53123" ixy="-2.46387e-07" ixz="-1.00789e-06" iyy="4.52016" iyz="-0.0313027" izz="0.892109"/>
    </inertial>
    <visual>
      <origin xyz="0 0 0.62" rpy="0 0 0"/>
      <geometry>
        <mesh filename="package://assets/pedestal.stl"/>
      </geometry>
      <material name="pedestal_material">
        <color rgba="0.25 0.25 0.25 1"/>
      </material>
    </visual>
    <collision>
      <origin xyz="0 0 0.62" rpy="0 0 0"/>
      <geometry>
        <mesh filename="package://assets/pedestal.stl"/>
      </geometry>
    </collision>
  </link>

  <!-- ==================== LINK: j1 ==================== -->
  <link name="j1">
    <inertial>
      <origin xyz="0.0251572 2.72802e-07 -0.0985614" rpy="0 0 0"/>
      <mass value="4.60977"/>
      <inertia ixx="0.0206874" ixy="-8.3691e-08" ixz="0.00306203" iyy="0.0205054" iyz="6.2555e-08" izz="0.00766358"/>
    </inertial>
    <visual>
      <origin xyz="0 0 0.1475" rpy="3.14159 0 0"/>
      <geometry>
        <mesh filename="package://assets/j1.stl"/>
      </geometry>
      <material name="j1_material">
        <color rgba="0.75 0.75 0.75 1"/>
      </material>
    </visual>
    <collision>
      <origin xyz="0 0 0.1475" rpy="3.14159 0 0"/>
      <geometry>
        <mesh filename="package://assets/j1.stl"/>
      </geometry>
    </collision>
  </link>

  <!-- ==================== LINK: j2_elbow ==================== -->
  <link name="j2_elbow">
    <inertial>
      <mass value="0.0"/>
      <inertia ixx="0" ixy="0" ixz="0" iyy="0" iyz="0" izz="0"/>
    </inertial>
    <visual>
      <origin xyz="-0.000436894 -0.365433 0.00617832" rpy="-1.5708 -1.5708 0"/>
      <geometry>
        <mesh filename="package://assets/j2_elbow.stl"/>
      </geometry>
      <material name="j2_elbow_material">
        <color rgba="1 0.5 0 1"/>
      </material>
    </visual>
    <collision>
      <origin xyz="-0.000436894 -0.365433 0.00617832" rpy="-1.5708 -1.5708 0"/>
      <geometry>
        <mesh filename="package://assets/j2_elbow.stl"/>
      </geometry>
    </collision>
  </link>

  <!-- ==================== LINK: j2 ==================== -->
  <link name="j2">
    <inertial>
      <origin xyz="-4.3248e-07 0.0437753 -0.0387002" rpy="0 0 0"/>
      <mass value="4.43336"/>
      <inertia ixx="0.0190197" ixy="-2.13955e-07" ixz="-2.3559e-08" iyy="0.00684907" iyz="-0.00303824" izz="0.0189104"/>
    </inertial>
    <visual>
      <origin xyz="0 -0.36 -0.01" rpy="-1.5708 -1.5708 0"/>
      <geometry>
        <mesh filename="package://assets/j2.stl"/>
      </geometry>
      <material name="j2_material">
        <color rgba="0.75 0.75 0.75 1"/>
      </material>
    </visual>
    <collision>
      <origin xyz="0 -0.36 -0.01" rpy="-1.5708 -1.5708 0"/>
      <geometry>
        <mesh filename="package://assets/j2.stl"/>
      </geometry>
    </collision>
  </link>

  <!-- ==================== LINK: j3 ==================== -->
  <link name="j3">
    <inertial>
      <mass value="0.0"/>
      <inertia ixx="0" ixy="0" ixz="0" iyy="0" iyz="0" izz="0"/>
    </inertial>
    <visual>
      <origin xyz="0.000191206 0.00086991 0.565491" rpy="3.14159 0 0"/>
      <geometry>
        <mesh filename="package://assets/j3.stl"/>
      </geometry>
      <material name="j3_material">
        <color rgba="0.75 0.75 0.75 1"/>
      </material>
    </visual>
    <collision>
      <origin xyz="0.000191206 0.00086991 0.565491" rpy="3.14159 0 0"/>
      <geometry>
        <mesh filename="package://assets/j3.stl"/>
      </geometry>
    </collision>
  </link>

  <!-- ==================== LINK: j3_base ==================== -->
  <link name="j3_base">
    <inertial>
      <origin xyz="-0.0218857 0.000220362 -0.101607" rpy="0 0 0"/>
      <mass value="3.56266"/>
      <inertia ixx="0.0148039" ixy="7.91072e-06" ixz="-0.00302454" iyy="0.0155916" iyz="3.0418e-05" izz="0.00472762"/>
    </inertial>
    <visual>
      <origin xyz="4.40555e-06 0.000872465 0.5545" rpy="3.14159 0 0"/>
      <geometry>
        <mesh filename="package://assets/j3_base.stl"/>
      </geometry>
      <material name="j3_base_material">
        <color rgba="1 1 1 1"/>
      </material>
    </visual>
    <collision>
      <origin xyz="4.40555e-06 0.000872465 0.5545" rpy="3.14159 0 0"/>
      <geometry>
        <mesh filename="package://assets/j3_base.stl"/>
      </geometry>
    </collision>
  </link>

  <!-- ==================== LINK: j4 ==================== -->
  <link name="j4">
    <inertial>
      <origin xyz="5.32542e-05 0.0501868 -0.0333238" rpy="0 0 0"/>
      <mass value="3.07361"/>
      <inertia ixx="0.010696" ixy="-7.40333e-06" ixz="-1.94771e-06" iyy="0.00381625" iyz="-0.00177027" izz="0.0101929"/>
    </inertial>
    <visual>
      <origin xyz="0.000865672 -0.786735 0.00615927" rpy="-1.5708 1.5607 0"/>
      <geometry>
        <mesh filename="package://assets/j4.stl"/>
      </geometry>
      <material name="j4_material">
        <color rgba="0.75 0.75 0.75 1"/>
      </material>
    </visual>
    <collision>
      <origin xyz="0.000865672 -0.786735 0.00615927" rpy="-1.5708 1.5607 0"/>
      <geometry>
        <mesh filename="package://assets/j4.stl"/>
      </geometry>
    </collision>
  </link>

  <!-- ==================== LINK: j4_elbow ==================== -->
  <link name="j4_elbow">
    <inertial>
      <mass value="0.0"/>
      <inertia ixx="0" ixy="0" ixz="0" iyy="0" iyz="0" izz="0"/>
    </inertial>
    <visual>
      <origin xyz="0.000865211 -0.786736 0.00615955" rpy="-1.5708 1.5607 0"/>
      <geometry>
        <mesh filename="package://assets/j4_elbow.stl"/>
      </geometry>
      <material name="j4_elbow_material">
        <color rgba="1 0.5 0 1"/>
      </material>
    </visual>
    <collision>
      <origin xyz="0.000865211 -0.786736 0.00615955" rpy="-1.5708 1.5607 0"/>
      <geometry>
        <mesh filename="package://assets/j4_elbow.stl"/>
      </geometry>
    </collision>
  </link>

  <!-- ==================== LINK: j5 ==================== -->
  <link name="j5">
    <inertial>
      <mass value="0.0"/>
      <inertia ixx="0" ixy="0" ixz="0" iyy="0" iyz="0" izz="0"/>
    </inertial>
    <visual>
      <origin xyz="-1.04277e-05 -0.00146876 0.965489" rpy="-3.1405 -1.10139e-05 0"/>
      <geometry>
        <mesh filename="package://assets/j5.stl"/>
      </geometry>
      <material name="j5_material">
        <color rgba="0.75 0.75 0.75 1"/>
      </material>
    </visual>
    <collision>
      <origin xyz="-1.04277e-05 -0.00146876 0.965489" rpy="-3.1405 -1.10139e-05 0"/>
      <geometry>
        <mesh filename="package://assets/j5.stl"/>
      </geometry>
    </collision>
  </link>

  <!-- ==================== LINK: j5_base ==================== -->
  <link name="j5_base">
    <inertial>
      <origin xyz="-0.0159162 0.000205027 -0.0636206" rpy="0 0 0"/>
      <mass value="1.90041"/>
      <inertia ixx="0.00541091" ixy="1.13624e-05" ixz="-0.00192155" iyy="0.00626735" iyz="2.45837e-05" izz="0.00277913"/>
    </inertial>
    <visual>
      <origin xyz="-1.29963e-05 -0.0017231 0.954499" rpy="-3.1405 -1.10139e-05 0"/>
      <geometry>
        <mesh filename="package://assets/j5_base.stl"/>
      </geometry>
      <material name="j5_base_material">
        <color rgba="1 1 1 1"/>
      </material>
    </visual>
    <collision>
      <origin xyz="-1.29963e-05 -0.0017231 0.954499" rpy="-3.1405 -1.10139e-05 0"/>
      <geometry>
        <mesh filename="package://assets/j5_base.stl"/>
      </geometry>
    </collision>
  </link>

  <!-- ==================== LINK: j6 ==================== -->
  <link name="j6">
    <inertial>
      <origin xyz="3.86296e-07 0.0111225 -0.0528542" rpy="0 0 0"/>
      <mass value="2.37888"/>
      <inertia ixx="0.00476197" ixy="-3.31443e-07" ixz="-4.9663e-08" iyy="0.00243062" iyz="-0.000155968" izz="0.00463135"/>
    </inertial>
    <visual>
      <origin xyz="-0.000436372 -1.18076 -0.0527884" rpy="-1.5708 1.5607 0"/>
      <geometry>
        <mesh filename="package://assets/j6.stl"/>
      </geometry>
      <material name="j6_material">
        <color rgba="0.75 0.75 0.75 1"/>
      </material>
    </visual>
    <collision>
      <origin xyz="-0.000436372 -1.18076 -0.0527884" rpy="-1.5708 1.5607 0"/>
      <geometry>
        <mesh filename="package://assets/j6.stl"/>
      </geometry>
    </collision>
  </link>

  <!-- ==================== LINK: j6_elbow ==================== -->
  <link name="j6_elbow">
    <inertial>
      <mass value="0.0"/>
      <inertia ixx="0" ixy="0" ixz="0" iyy="0" iyz="0" izz="0"/>
    </inertial>
    <visual>
      <origin xyz="-0.000438397 -1.18076 -0.0527894" rpy="-1.5708 1.5607 0"/>
      <geometry>
        <mesh filename="package://assets/j6_elbow.stl"/>
      </geometry>
      <material name="j6_elbow_material">
        <color rgba="1 0.5 0 1"/>
      </material>
    </visual>
    <collision>
      <origin xyz="-0.000438397 -1.18076 -0.0527894" rpy="-1.5708 1.5607 0"/>
      <geometry>
        <mesh filename="package://assets/j6_elbow.stl"/>
      </geometry>
    </collision>
  </link>

  <!-- ==================== LINK: j7 ==================== -->
  <link name="j7">
    <inertial>
      <mass value="0.0"/>
      <inertia ixx="0" ixy="0" ixz="0" iyy="0" iyz="0" izz="0"/>
    </inertial>
    <visual>
      <origin xyz="-4.40555e-06 -1.19817 -0.0521929" rpy="-1.5708 1.5607 0"/>
      <geometry>
        <mesh filename="package://assets/j7.stl"/>
      </geometry>
      <material name="j7_material">
        <color rgba="1 1 1 1"/>
      </material>
    </visual>
    <collision>
      <origin xyz="-4.40555e-06 -1.19817 -0.0521929" rpy="-1.5708 1.5607 0"/>
      <geometry>
        <mesh filename="package://assets/j7.stl"/>
      </geometry>
    </collision>
  </link>

  <!-- ==================== FIXED JOINTS (all with identity transform) ==================== -->
  
  <joint name="fasten_base_to_pedestal" type="fixed">
    <origin xyz="0 0 0" rpy="0 0 0"/>
    <parent link="pedestal"/>
    <child link="base"/>
  </joint>

  <joint name="fasten_j2_elbow_to_j2" type="fixed">
    <origin xyz="0 0 0" rpy="0 0 0"/>
    <parent link="j2"/>
    <child link="j2_elbow"/>
  </joint>

  <joint name="fasten_j3_to_j3_base" type="fixed">
    <origin xyz="0 0 0" rpy="0 0 0"/>
    <parent link="j3_base"/>
    <child link="j3"/>
  </joint>

  <joint name="fasten_j4_elbow_to_j4" type="fixed">
    <origin xyz="0 0 0" rpy="0 0 0"/>
    <parent link="j4"/>
    <child link="j4_elbow"/>
  </joint>

  <joint name="fasten_j5_to_j5_base" type="fixed">
    <origin xyz="0 0 0" rpy="0 0 0"/>
    <parent link="j5_base"/>
    <child link="j5"/>
  </joint>

  <joint name="fasten_j6_elbow_to_j6" type="fixed">
    <origin xyz="0 0 0" rpy="0 0 0"/>
    <parent link="j6"/>
    <child link="j6_elbow"/>
  </joint>

  <joint name="fasten_j7_to_j6" type="fixed">
    <origin xyz="0 0 0" rpy="0 0 0"/>
    <parent link="j6"/>
    <child link="j7"/>
  </joint>

  <!-- ==================== REVOLUTE JOINTS ==================== -->
  
  <joint name="J1" type="revolute">
    <origin xyz="0 0 0.72831" rpy="3.14159 0 0"/>
    <parent link="pedestal"/>
    <child link="j1"/>
    <axis xyz="0 0 1"/>
    <limit effort="10" velocity="10" lower="-2.96706" upper="2.96706"/>
  </joint>

  <joint name="J2" type="revolute">
    <origin xyz="0.007444 0 -0.158185" rpy="-1.5708 0 -1.5708"/>
    <parent link="j1"/>
    <child link="j2"/>
    <axis xyz="0 0 1"/>
    <limit effort="10" velocity="10" lower="-2.0944" upper="2.0944"/>
  </joint>

  <joint name="J3" type="revolute">
    <origin xyz="0 0.144786 -0.007444" rpy="1.5708 -1.5708 0"/>
    <parent link="j2"/>
    <child link="j3_base"/>
    <axis xyz="0 0 1"/>
    <limit effort="10" velocity="10" lower="-2.96706" upper="2.96706"/>
  </joint>

  <joint name="J4" type="revolute">
    <origin xyz="-0.00767675 7.70322e-05 -0.167862" rpy="-1.5708 0 1.5607"/>
    <parent link="j3_base"/>
    <child link="j4"/>
    <axis xyz="0 0 1"/>
    <limit effort="10" velocity="10" lower="-2.0944" upper="2.0944"/>
  </joint>

  <joint name="J5" type="revolute">
    <origin xyz="0.000141668 0.129898 -0.0078162" rpy="1.5708 1.5607 -0.00109061"/>
    <parent link="j4"/>
    <child link="j5_base"/>
    <axis xyz="0 0 1"/>
    <limit effort="10" velocity="10" lower="-2.96706" upper="2.96706"/>
  </joint>

  <joint name="J6" type="revolute">
    <origin xyz="-0.0526245 0.000720817 -0.167862" rpy="-1.5708 -0.00109061 1.5607"/>
    <parent link="j5_base"/>
    <child link="j6"/>
    <axis xyz="0 0 1"/>
    <limit effort="10" velocity="10" lower="-2.0944" upper="2.0944"/>
  </joint>

<!-- Add this section after your joints, before the closing </robot> tag -->
  
  <!-- ==================== DISABLE COLLISIONS ==================== -->
  <!-- Prevent pedestal from colliding with moving joints -->
  <disable_collisions link1="pedestal" link2="j1"/>
  <disable_collisions link1="pedestal" link2="j2"/>
  <disable_collisions link1="pedestal" link2="j2_elbow"/>
  <disable_collisions link1="pedestal" link2="j3_base"/>
  <disable_collisions link1="pedestal" link2="j3"/>
  <disable_collisions link1="pedestal" link2="j4"/>
  <disable_collisions link1="pedestal" link2="j4_elbow"/>
  <disable_collisions link1="pedestal" link2="j5_base"/>
  <disable_collisions link1="pedestal" link2="j5"/>
  <disable_collisions link1="pedestal" link2="j6"/>
  <disable_collisions link1="pedestal" link2="j6_elbow"/>
  <disable_collisions link1="pedestal" link2="j7"/>

  <!-- Also disable base collisions if needed -->
  <disable_collisions link1="base" link2="j1"/>
  <disable_collisions link1="base" link2="j2"/>
  <!-- ... add more as needed -->

</robot>